//
// Created by Flavia Rivero on 2/11/24.
//

#include "excepcion_no_capturada.h"

void lanzaExcepcion6() {
    throw std::runtime_error("Error en la funci√≥n lanzaExcepcion");
}

